Workbook
Name Slicer_Decade: #N/A
Name Slicer_Genre: #N/A
Name Slicer_Language: #N/A

Sheet Data_Info
E3: Shape
E4: Rows | F4: Columns | H4: Null values Count
E5: =COUNTA('IMDB Movie Database'!A2:A3727) -> 3726 | F5: =COUNTA('IMDB Movie Database'!A1:R1) -> 18 | H5: Title | I5: Release Date | J5: Color/B&W | K5: Genre | L5: Language | M5: Country | N5: Rating | O5: Lead Actor | P5: Director Name | Q5: Lead Actor FB Likes | R5: Cast FB Likes | S5: Director FB Likes | T5: Movie FB Likes | U5: IMDb Score (1-10) | V5: Total Reviews | W5: Duration (min) | X5: Gross Revenue | Y5: Budget
H6: =COUNTBLANK('IMDB Movie Database'!A2:A3727) -> 0 | I6: =COUNTBLANK('IMDB Movie Database'!B2:B3727) -> 0 | J6: =COUNTBLANK('IMDB Movie Database'!C2:C3727) -> 0 | K6: =COUNTBLANK('IMDB Movie Database'!D2:D3727) -> 0 | L6: =COUNTBLANK('IMDB Movie Database'!E2:E3727) -> 2 | M6: =COUNTBLANK('IMDB Movie Database'!F2:F3727) -> 0 | N6: =COUNTBLANK('IMDB Movie Database'!G2:G3727) -> 49 | O6: =COUNTBLANK('IMDB Movie Database'!H2:H3727) -> 3 | ... Y6: =COUNTBLANK('IMDB Movie Database'!R2:R3727) -> 0
D9: Statistical Measure
D10: Statistical Measure | E10: Title | F10: Release Date | G10: Color/B&W | H10: Genre | I10: Language | J10: Country | K10: Rating | L10: Lead Actor | M10: Director Name | N10: Lead Actor FB Likes | O10: Cast FB Likes | P10: Director FB Likes | Q10: Movie FB Likes | R10: IMDb Score (1-10) | S10: Total Reviews | T10: Duration (min) | U10: Gross Revenue | V10: Budget
D11: count | E11: =COUNTA('IMDB Movie Database'!A2:A3727) -> 3726 | F11: =COUNTA('IMDB Movie Database'!B2:B3727) -> 3726 | G11: =COUNTA('IMDB Movie Database'!C2:C3727) -> 3726 | H11: =COUNTA('IMDB Movie Database'!D2:D3727) -> 3726 | I11: =COUNTA('IMDB Movie Database'!E2:E3727) -> 3724 | J11: =COUNTA('IMDB Movie Database'!F2:F3727) -> 3726 | K11: =COUNTA('IMDB Movie Database'!G2:G3727) -> 3677 | L11: =COUNTA('IMDB Movie Database'!H2:H3727) -> 3723 | ... V11: =COUNTA('IMDB Movie Database'!R2:R3727) -> 3726
D12: Mean | N12: =AVERAGE('IMDB Movie Database'!J2:J3727) -> 7467.9498 | O12: =AVERAGE('IMDB Movie Database'!K2:K3727) -> 11052.391 | P12: =AVERAGE('IMDB Movie Database'!L2:L3727) -> 793.09071 | Q12: =AVERAGE('IMDB Movie Database'!M2:M3727) -> 8621.7246 | R12: =AVERAGE('IMDB Movie Database'!N2:N3727) -> 6.463956 | S12: =AVERAGE('IMDB Movie Database'!O2:O3727) -> 159.89262 | T12: =AVERAGE('IMDB Movie Database'!P2:P3727) -> 109.7745 | U12: =AVERAGE('IMDB Movie Database'!Q2:Q3727) -> 49729300 | V12: =AVERAGE('IMDB Movie Database'!R2:R3727) -> 44357968
D13: std | N13: =_xlfn.STDEV.S('IMDB Movie Database'!J2:J3727) -> 15524.904 | O13: =_xlfn.STDEV.S('IMDB Movie Database'!K2:K3727) -> 18956.09 | P13: =_xlfn.STDEV.S('IMDB Movie Database'!L2:L3727) -> 3054.6348 | Q13: =_xlfn.STDEV.S('IMDB Movie Database'!M2:M3727) -> 20793.501 | R13: =_xlfn.STDEV.S('IMDB Movie Database'!N2:N3727) -> 1.0588444 | S13: =_xlfn.STDEV.S('IMDB Movie Database'!O2:O3727) -> 122.40478 | T13: =_xlfn.STDEV.S('IMDB Movie Database'!P2:P3727) -> 22.846089 | U13: =_xlfn.STDEV.S('IMDB Movie Database'!Q2:Q3727) -> 68173099 | V13: =_xlfn.STDEV.S('IMDB Movie Database'!R2:R3727) -> 2.2682128e+08
D14: min | N14: =MIN('IMDB Movie Database'!J2:J3727) -> 0 | O14: =MIN('IMDB Movie Database'!K2:K3727) -> 0 | P14: =MIN('IMDB Movie Database'!L2:L3727) -> 0 | Q14: =MIN('IMDB Movie Database'!M2:M3727) -> 0 | R14: =MIN('IMDB Movie Database'!N2:N3727) -> 1.6 | S14: =MIN('IMDB Movie Database'!O2:O3727) -> 1 | T14: =MIN('IMDB Movie Database'!P2:P3727) -> 34 | U14: =MIN('IMDB Movie Database'!Q2:Q3727) -> 162 | V14: =MIN('IMDB Movie Database'!R2:R3727) -> 218
D15: max | N15: =MAX('IMDB Movie Database'!J2:J3727) -> 640000 | O15: =MAX('IMDB Movie Database'!K2:K3727) -> 656730 | P15: =MAX('IMDB Movie Database'!L2:L3727) -> 23000 | Q15: =MAX('IMDB Movie Database'!M2:M3727) -> 349000 | R15: =MAX('IMDB Movie Database'!N2:N3727) -> 9.3 | S15: =MAX('IMDB Movie Database'!O2:O3727) -> 813 | T15: =MAX('IMDB Movie Database'!P2:P3727) -> 330 | U15: =MAX('IMDB Movie Database'!Q2:Q3727) -> 760505847 | V15: =MAX('IMDB Movie Database'!R2:R3727) -> 12215500000
D16: Unique Count | E16: =COUNTA(_xlfn.UNIQUE('IMDB Movie Database'!A2:A3727)) -> 3726 | G16: =COUNTA(_xlfn.UNIQUE('IMDB Movie Database'!C2:C3727)) -> 2 | H16: =COUNTA(_xlfn.UNIQUE('IMDB Movie Database'!D2:D3727)) -> 17 | I16: =COUNTA(_xlfn.UNIQUE('IMDB Movie Database'!E2:E3727)) -> 39 | J16: =COUNTA(_xlfn.UNIQUE('IMDB Movie Database'!F2:F3727)) -> 46 | K16: =COUNTA(_xlfn.UNIQUE('IMDB Movie Database'!G2:G3727)) -> 13 | L16: =COUNTA(_xlfn.UNIQUE('IMDB Movie Database'!H2:H3727)) -> 1495 | M16: =COUNTA(_xlfn.UNIQUE('IMDB Movie Database'!I2:I3727)) -> 1733 | N16: =COUNTA(_xlfn.UNIQUE('IMDB Movie Database'!J2:J3727)) -> 735 | ... V16: =COUNTA(_xlfn.UNIQUE('IMDB Movie Database'!R2:R3727)) -> 370

Sheet IMDB Movie Database
A1: Title | B1: Release Date | C1: Color/B&W | D1: Genre | E1: Language | F1: Country | G1: Rating | H1: Lead Actor | I1: Director Name | J1: Lead Actor FB Likes | K1: Cast FB Likes | L1: Director FB Likes | M1: Movie FB Likes | N1: IMDb Score (1-10) | O1: Total Reviews | P1: Duration (min) | Q1: Gross Revenue | R1: Budget
A2: Anchorman: The Legend of Ron Burgundy | B2: 38129 | C2: Color | D2: Comedy | E2: English | F2: USA | G2: PG-13 | H2: Darcy Donavan | I2: Adam McKay | J2: 640000 | K2: 656730 | L2: 285 | M2: 0 | N2: 7.2 | O2: 181 | P2: 98 | Q2: 84136909 | R2: 26000000
A3: Hardflip | B3: 41138 | C3: Color | D3: Action | E3: English | F3: USA | G3: PG-13 | H3: Matthew Ziff | I3: Johnny Remo | J3: 260000 | K3: 263584 | L3: 74 | M3: 706 | N3: 5.6 | O3: 2 | P3: 112 | Q3: 96734 | R3: 1000000 | T3: =COUNTBLANK(A2:R3726) -> 55
A4: The Final Destination | B4: 40064 | C4: Color | D4: Horror | E4: English | F4: USA | G4: R | H4: Krista Allen | I4: David R. Ellis | J4: 164000 | K4: 303717 | L4: 160 | M4: 0 | N4: 5.2 | O4: 221 | P4: 82 | Q4: 66466372 | R4: 40000000
A5: Quarantine | B5: 39762 | C5: Color | D5: Horror | E5: English | F5: USA | G5: R | H5: Andrew Fiscella | I5: John Erick Dowdle | J5: 137000 | K5: 140268 | L5: 66 | M5: 0 | N5: 6 | O5: 198 | P5: 89 | Q5: 31691811 | R5: 12000000 | U5: =CORREL(IMDB[IMDb Score (1-10)],IMDB[Lead Actor FB Likes]) -> 0.091218506
A6: Armored | B6: 39838 | C6: Color | D6: Action | E6: English | F6: USA | G6: PG-13 | H6: Andrew Fiscella | I6: NimrÃ³d Antal | J6: 137000 | K6: 137712 | L6: 190 | M6: 0 | N6: 5.7 | O6: 107 | P6: 88 | Q6: 15988876 | R6: 27000000
A7: Evan Almighty | B7: 39424 | C7: Color | D7: Comedy | E7: English | F7: USA | G7: PG | H7: Jimmy Bennett | I7: Tom Shadyac | J7: 87000 | K7: 108016 | L7: 293 | M7: 2000 | N7: 5.4 | O7: 186 | P7: 96 | Q7: 100289690 | R7: 175000000
A8: The Amityville Horror | B8: 38591 | C8: Color | D8: Drama | E8: English | F8: USA | G8: R | H8: Jimmy Bennett | I8: Andrew Douglas | J8: 87000 | K8: 120797 | L8: 15 | M8: 0 | N8: 6 | O8: 220 | P8: 90 | Q8: 64255243 | R8: 19000000
A9: Poseidon | B9: 38786 | C9: Color | D9: Action | E9: English | F9: USA | G9: PG-13 | H9: Jimmy Bennett | I9: Wolfgang Petersen | J9: 87000 | K9: 92456 | L9: 249 | M9: 0 | N9: 5.6 | O9: 231 | P9: 98 | Q9: 60655503 | R9: 160000000
A10: Firewall | B10: 39027 | C10: Color | D10: Crime | E10: English | F10: USA | G10: PG-13 | H10: Jimmy Bennett | I10: Richard Loncraine | J10: 87000 | K10: 101383 | L10: 12 | M10: 773 | N10: 5.8 | O10: 171 | P10: 105 | Q10: 48745150 | R10: 50000000
A11: Hostage | B11: 38678 | C11: Color | D11: Action | E11: English | F11: USA | G11: R | H11: Jimmy Bennett | I11: Florent-Emilio Siri | J11: 87000 | K11: 103354 | L11: 17 | M11: 0 | N11: 6.6 | O11: 152 | P11: 113 | Q11: 34636443 | R11: 52000000
A12: Shorts | B12: 39919 | C12: Color | D12: Comedy | E12: English | F12: USA | G12: PG | H12: Jimmy Bennett | I12: Robert Rodriguez | J12: 87000 | K12: 88422 | L12: 0 | M12: 431 | N12: 4.9 | O12: 103 | P12: 89 | Q12: 20916309 | R12: 40000000
A13: Trucker | B13: 39619 | C13: Color | D13: Drama | E13: English | F13: USA | G13: R | H13: Jimmy Bennett | I13: James Mottern | J13: 87000 | K13: 89263 | L13: 7 | M13: 371 | N13: 6.7 | O13: 46 | P13: 90 | Q13: 52166 | R13: 2000000
A14: The Grace Card | B14: 40498 | C14: Color | D14: Drama | E14: English | F14: USA | G14: PG-13 | H14: Michael Joiner | I14: David G. Evans | J14: 77000 | K14: 77046 | L14: 0 | M14: 0 | N14: 6.4 | O14: 25 | P14: 101 | Q14: 2428241 | R14: 200000 | W14: hours studies | Y14: Marks | AB14: watching hours | AC14: marks
A15: Night at the Museum | B15: 38835 | C15: Color | D15: Action | E15: English | F15: USA | G15: PG | H15: Robin Williams | I15: Shawn Levy | J15: 49000 | K15: 55486 | L15: 189 | M15: 3000 | N15: 6.4 | O15: 179 | P15: 108 | Q15: 250863268 | R15: 110000000 | W15: 1 | Y15: 10 | AB15: 5 | AC15: 10
A16: Mrs. Doubtfire | B16: 34227 | C16: Color | D16: Comedy | E16: English | F16: USA | G16: PG-13 | H16: Robin Williams | I16: Chris Columbus | J16: 49000 | K16: 52201 | L16: 0 | M16: 0 | N16: 6.9 | O16: 57 | P16: 125 | Q16: 219200000 | R16: 25000000 | W16: 2 | Y16: 20 | AB16: 4 | AC16: 20
A17: Aladdin | B17: 33910 | C17: Color | D17: Adventure | E17: English | F17: USA | G17: G | H17: Robin Williams | I17: Ron Clements | J17: 49000 | K17: 52970 | L17: 63 | M17: 0 | N17: 8 | O17: 124 | P17: 90 | Q17: 217350219 | R17: 28000000 | W17: 3 | Y17: 30 | AB17: 3 | AC17: 30
A18: Happy Feet | B18: 38758 | C18: Color | D18: Animation | E18: English | F18: USA | G18: PG | H18: Robin Williams | I18: George Miller | J18: 49000 | K18: 70996 | L18: 750 | M18: 0 | N18: 6.5 | O18: 206 | P18: 108 | Q18: 197992827 | R18: 100000000 | W18: 4 | Y18: 40 | AB18: 2 | AC18: 40
A19: Night at the Museum: Battle of the Smithsonian | B19: 40011 | C19: Color | D19: Adventure | E19: English | F19: USA | G19: PG | H19: Robin Williams | I19: Shawn Levy | J19: 49000 | K19: 54039 | L19: 189 | M19: 2000 | N19: 5.9 | O19: 185 | P19: 105 | Q19: 177243721 | R19: 150000000 | W19: 5 | Y19: 50 | AB19: 1 | AC19: 50
A20: Good Will Hunting | B20: 35562 | C20: Color | D20: Drama | E20: English | F20: USA | G20: R | H20: Robin Williams | I20: Gus Van Sant | J20: 49000 | K20: 63710 | L20: 835 | M20: 31000 | N20: 8.3 | O20: 161 | P20: 126 | Q20: 138339411 | R20: 10000000
A21: Patch Adams | B21: 35803 | C21: Color | D21: Biography | E21: English | F21: USA | G21: PG-13 | H21: Robin Williams | I21: Tom Shadyac | J21: 49000 | K21: 74382 | L21: 293 | M21: 0 | N21: 6.7 | O21: 55 | P21: 115 | Q21: 135014968 | R21: 50000000
A22: Good Morning, Vietnam | B22: 31858 | C22: Color | D22: Biography | E22: English | F22: USA | G22: R | H22: Robin Williams | I22: Barry Levinson | J22: 49000 | K22: 50141 | L22: 272 | M22: 0 | N22: 7.3 | O22: 62 | P22: 121 | Q22: 123922370 | R22: 13000000
A23: Hook | B23: 33368 | C23: Color | D23: Adventure | E23: English | F23: USA | G23: PG | H23: Robin Williams | I23: Steven Spielberg | J23: 49000 | K23: 64259 | L23: 14000 | M23: 13000 | N23: 6.7 | O23: 75 | P23: 142 | Q23: 119654900 | R23: 70000000
A24: Night at the Museum: Secret of the Tomb | B24: 41645 | C24: Color | D24: Adventure | E24: English | F24: USA | G24: PG | H24: Robin Williams | I24: Shawn Levy | J24: 49000 | K24: 53587 | L24: 189 | M24: 11000 | N24: 6.2 | O24: 154 | P24: 98 | Q24: 113733726 | R24: 127000000
A25: Dead Poets Society | B25: 32512 | C25: Color | D25: Comedy | E25: English | F25: USA | G25: PG | H25: Robin Williams | I25: Peter Weir | J25: 49000 | K25: 51609 | L25: 608 | M25: 23000 | N25: 8 | O25: 96 | P25: 128 | Q25: 95860116 | R25: 16400000
A26: Flubber | B26: 35744 | C26: Color | D26: Comedy | E26: English | F26: USA | G26: PG | H26: Robin Williams | I26: Les Mayfield | J26: 49000 | K26: 50005 | L26: 10 | M26: 0 | N26: 5.2 | O26: 53 | P26: 90 | Q26: 92969824 | R26: 80000000
A27: Happy Feet 2 | B27: 40769 | C27: Color | D27: Animation | E27: English | F27: Australia | G27: PG | H27: Robin Williams | I27: George Miller | J27: 49000 | K27: 62644 | L27: 750 | M27: 0 | N27: 5.9 | O27: 156 | P27: 100 | Q27: 63992328 | R27: 135000000
A28: Bicentennial Man | B28: 36164 | C28: Color | D28: Comedy | E28: English | F28: USA | G28: PG | H28: Robin Williams | I28: Chris Columbus | J28: 49000 | K28: 55254 | L28: 0 | M28: 0 | N28: 6.8 | O28: 93 | P28: 132 | Q28: 58220776 | R28: 100000000
A29: What Dreams May Come | B29: 35874 | C29: Color | D29: Drama | E29: English | F29: USA | G29: PG-13 | H29: Robin Williams | I29: Vincent Ward | J29: 49000 | K29: 49631 | L29: 25 | M29: 32000 | N29: 7 | O29: 121 | P29: 113 | Q29: 55350897 | R29: 85000000
A30: Old Dogs | B30: 39941 | C30: Color | D30: Comedy | E30: English | F30: USA | G30: PG | H30: Robin Williams | I30: Walt Becker | J30: 49000 | K30: 53370 | L30: 12 | M30: 0 | N30: 5.4 | O30: 124 | P30: 88 | Q30: 49474048 | R30: 35000000
A31: License to Wed | B31: 39254 | C31: Color | D31: Comedy | E31: English | F31: USA | G31: PG-13 | H31: Robin Williams | I31: Ken Kwapis | J31: 49000 | K31: 52566 | L31: 42 | M31: 913 | N31: 5.3 | O31: 120 | P31: 91 | Q31: 43792641 | R31: 35000000 | AA31: 1
A32: Man of the Year | B32: 38963 | C32: Color | D32: Comedy | E32: English | F32: USA | G32: PG-13 | H32: Robin Williams | I32: Barry Levinson | J32: 49000 | K32: 52571 | L32: 272 | M32: 0 | N32: 6.2 | O32: 111 | P32: 115 | Q32: 37442180 | R32: 20000000 | AA32: 3
A33: August Rush | B33: 39161 | C33: Color | D33: Drama | E33: English | F33: USA | G33: PG | H33: Robin Williams | I33: Kirsten Sheridan | J33: 49000 | K33: 50927 | L33: 59 | M33: 18000 | N33: 7.5 | O33: 148 | P33: 114 | Q33: 31655091 | R33: 30000000 | AA33: 2
A34: One Hour Photo | B34: 37578 | C34: Color | D34: Drama | E34: English | F34: USA | G34: R | H34: Robin Williams | I34: Mark Romanek | J34: 49000 | K34: 52138 | L34: 132 | M34: 0 | N34: 6.8 | O34: 207 | P34: 96 | Q34: 31597131 | R34: 12000000 | AA34: 5
A35: The Big Wedding | B35: 41534 | C35: Color | D35: Comedy | E35: English | F35: USA | G35: R | H35: Robin Williams | I35: Justin Zackham | J35: 49000 | K35: 74181 | L35: 16 | M35: 0 | N35: 5.6 | O35: 133 | P35: 89 | Q35: 21784432 | R35: 35000000 | AA35: 5
A36: Death to Smoochy | B36: 37352 | C36: Color | D36: Comedy | E36: English | F36: UK | G36: R | H36: Robin Williams | I36: Danny DeVito | J36: 49000 | K36: 52885 | L36: 0 | M36: 0 | N36: 6.4 | O36: 105 | P36: 109 | Q36: 8355815 | R36: 55000000 | AA36: 3
A37: The Night Listener | B37: 38728 | C37: Color | D37: Crime | E37: English | F37: USA | G37: R | H37: Robin Williams | I37: Patrick Stettner | J37: 49000 | K37: 50831 | L37: 5 | M37: 576 | N37: 5.9 | O37: 125 | P37: 81 | Q37: 7825820 | R37: 4000000 | AA37: 5
A38: Jakob the Liar | B38: 36228 | C38: Color | D38: Drama | E38: English | F38: France | G38: PG-13 | H38: Robin Williams | I38: Peter Kassovitz | J38: 49000 | K38: 51657 | L38: 0 | M38: 0 | N38: 6.5 | O38: 68 | P38: 120 | Q38: 4956401 | R38: 15000000 | AA38: 5
A39: House of D | B39: 38236 | C39: Color | D39: Comedy | E39: English | F39: USA | G39: PG-13 | H39: Robin Williams | I39: David Duchovny | J39: 49000 | K39: 51441 | L39: 0 | M39: 857 | N39: 7 | O39: 46 | P39: 96 | Q39: 371081 | R39: 6000000 | AA39: 4
A40: Certifiably Jonathan | B40: 39324 | C40: Color | D40: Comedy | E40: English | F40: USA | H40: Robin Williams | I40: James David Pasternak | J40: 49000 | K40: 54484 | L40: 0 | M40: 87 | N40: 6.2 | O40: 17 | P40: 85 | Q40: 7826 | R40: 1200000
...

Sheet Cleaned_Data_&_Helper_Columns
A1: Title | B1: Release Date | C1: Year | D1: Decade | E1: Color/B&W | F1: Genre | G1: Language | H1: Country | I1: Rating | J1: Lead Actor | K1: Director Name | L1: Lead Actor FB Likes | M1: Cast FB Likes | N1: Director FB Likes | O1: Movie FB Likes | P1: IMDb Score (1-10) | Q1: Total Reviews | R1: Duration (min) | S1: Gross Revenue | T1: Budget | U1: Profit | V1: Hit/Flop | W1: Rating Category | X1: Movie Length Category
A2: Anchorman: The Legend of Ron Burgundy | B2: 38129 | C2: =YEAR(IMDB4[[#This Row],[Release Date]]) -> 2004 | D2: =FLOOR(IMDB4[[#This Row],[Year]],10)&"s" -> 2000s | E2: Color | F2: Comedy | G2: English | H2: USA | I2: PG-13 | J2: Darcy Donavan | K2: Adam McKay | L2: 640000 | M2: 656730 | N2: 285 | O2: 0 | P2: 7.2 | Q2: 181 | R2: 98 | S2: 84136909 | T2: 26000000 | U2: =IMDB4[[#This Row],[Gross Revenue]]-IMDB4[[#This Row],[Budget]] -> 58136909 | V2: =IF(IMDB4[[#This Row],[Profit]]>0,"Hit","Flop") -> Hit | W2: {=_xlfn.IFS(IMDB4[[#This Row],[IMDb Score (1-10)]]>=8,"Excellent",IMDB4[[#This Row],[IMDb Score (1-10)]]>=7,"Good",IMDB4[[#This Row],[IMDb Score (1-10)]]>=5,"Average",TRUE,"Poor")} -> Good | X2: =IF(IMDB4[[#This Row],[Duration (min)]]<90,"Short",IF(IMDB4[[#This Row],[Duration (min)]]<=120,"Medium", "Long")) -> Medium
A3: Hardflip | B3: 41138 | C3: =YEAR(IMDB4[[#This Row],[Release Date]]) -> 2012 | D3: =FLOOR(IMDB4[[#This Row],[Year]],10)&"s" -> 2010s | E3: Color | F3: Action | G3: English | H3: USA | I3: PG-13 | J3: Matthew Ziff | K3: Johnny Remo | L3: 260000 | M3: 263584 | N3: 74 | O3: 706 | P3: 5.6 | Q3: 2 | R3: 112 | S3: 96734 | T3: 1000000 | U3: =IMDB4[[#This Row],[Gross Revenue]]-IMDB4[[#This Row],[Budget]] -> -903266 | V3: =IF(IMDB4[[#This Row],[Profit]]>0,"Hit","Flop") -> Flop | W3: {=_xlfn.IFS(IMDB4[[#This Row],[IMDb Score (1-10)]]>=8,"Excellent",IMDB4[[#This Row],[IMDb Score (1-10)]]>=7,"Good",IMDB4[[#This Row],[IMDb Score (1-10)]]>=5,"Average",TRUE,"Poor")} -> Average | X3: =IF(IMDB4[[#This Row],[Duration (min)]]<90,"Short",IF(IMDB4[[#This Row],[Duration (min)]]<=120,"Medium", "Long")) -> Medium
A4: The Final Destination | B4: 40064 | C4: =YEAR(IMDB4[[#This Row],[Release Date]]) -> 2009 | D4: =FLOOR(IMDB4[[#This Row],[Year]],10)&"s" -> 2000s | E4: Color | F4: Horror | G4: English | H4: USA | I4: R | J4: Krista Allen | K4: David R. Ellis | L4: 164000 | M4: 303717 | N4: 160 | O4: 0 | P4: 5.2 | Q4: 221 | R4: 82 | S4: 66466372 | T4: 40000000 | U4: =IMDB4[[#This Row],[Gross Revenue]]-IMDB4[[#This Row],[Budget]] -> 26466372 | V4: =IF(IMDB4[[#This Row],[Profit]]>0,"Hit","Flop") -> Hit | W4: {=_xlfn.IFS(IMDB4[[#This Row],[IMDb Score (1-10)]]>=8,"Excellent",IMDB4[[#This Row],[IMDb Score (1-10)]]>=7,"Good",IMDB4[[#This Row],[IMDb Score (1-10)]]>=5,"Average",TRUE,"Poor")} -> Average | X4: =IF(IMDB4[[#This Row],[Duration (min)]]<90,"Short",IF(IMDB4[[#This Row],[Duration (min)]]<=120,"Medium", "Long")) -> Short | AA4: Cavite | AB4: Fantasy
A5: Quarantine | B5: 39762 | C5: =YEAR(IMDB4[[#This Row],[Release Date]]) -> 2008 | D5: =FLOOR(IMDB4[[#This Row],[Year]],10)&"s" -> 2000s | E5: Color | F5: Horror | G5: English | H5: USA | I5: R | J5: Andrew Fiscella | K5: John Erick Dowdle | L5: 137000 | M5: 140268 | N5: 66 | O5: 0 | P5: 6 | Q5: 198 | R5: 89 | S5: 31691811 | T5: 12000000 | U5: =IMDB4[[#This Row],[Gross Revenue]]-IMDB4[[#This Row],[Budget]] -> 19691811 | V5: =IF(IMDB4[[#This Row],[Profit]]>0,"Hit","Flop") -> Hit | W5: {=_xlfn.IFS(IMDB4[[#This Row],[IMDb Score (1-10)]]>=8,"Excellent",IMDB4[[#This Row],[IMDb Score (1-10)]]>=7,"Good",IMDB4[[#This Row],[IMDb Score (1-10)]]>=5,"Average",TRUE,"Poor")} -> Average | X5: =IF(IMDB4[[#This Row],[Duration (min)]]<90,"Short",IF(IMDB4[[#This Row],[Duration (min)]]<=120,"Medium", "Long")) -> Short
A6: Armored | B6: 39838 | C6: =YEAR(IMDB4[[#This Row],[Release Date]]) -> 2009 | D6: =FLOOR(IMDB4[[#This Row],[Year]],10)&"s" -> 2000s | E6: Color | F6: Action | G6: English | H6: USA | I6: PG-13 | J6: Andrew Fiscella | K6: NimrÃ³d Antal | L6: 137000 | M6: 137712 | N6: 190 | O6: 0 | P6: 5.7 | Q6: 107 | R6: 88 | S6: 15988876 | T6: 27000000 | U6: =IMDB4[[#This Row],[Gross Revenue]]-IMDB4[[#This Row],[Budget]] -> -11011124 | V6: =IF(IMDB4[[#This Row],[Profit]]>0,"Hit","Flop") -> Flop | W6: {=_xlfn.IFS(IMDB4[[#This Row],[IMDb Score (1-10)]]>=8,"Excellent",IMDB4[[#This Row],[IMDb Score (1-10)]]>=7,"Good",IMDB4[[#This Row],[IMDb Score (1-10)]]>=5,"Average",TRUE,"Poor")} -> Average | X6: =IF(IMDB4[[#This Row],[Duration (min)]]<90,"Short",IF(IMDB4[[#This Row],[Duration (min)]]<=120,"Medium", "Long")) -> Short | AB6: {=_xlfn._xlws.FILTER(IMDB4[#All],IMDB4[[#All],[Title]]=AA4,IMDB4[[#All],[Genre]]=AB4)} -> Cavite | AC6: 38555 | AD6: 2005 | AE6: 2000s | AF6: Color | AG6: Thriller | AH6: English | AI6: Philippines | AJ6: Not Rated | AK6: Ian Gamazon | AL6: Neill Dela Llana | AM6: 0 | AN6: 0 | AO6: 0 | AP6: 74 | AQ6: 6.3 | AR6: 35 | AS6: 80 | AT6: 70071 | AU6: 7000 | AV6: 63071 | AW6: Hit | AX6: Average | AY6: Short
A7: Evan Almighty | B7: 39424 | C7: =YEAR(IMDB4[[#This Row],[Release Date]]) -> 2007 | D7: =FLOOR(IMDB4[[#This Row],[Year]],10)&"s" -> 2000s | E7: Color | F7: Comedy | G7: English | H7: USA | I7: PG | J7: Jimmy Bennett | K7: Tom Shadyac | L7: 87000 | M7: 108016 | N7: 293 | O7: 2000 | P7: 5.4 | Q7: 186 | R7: 96 | S7: 100289690 | T7: 175000000 | U7: =IMDB4[[#This Row],[Gross Revenue]]-IMDB4[[#This Row],[Budget]] -> -74710310 | V7: =IF(IMDB4[[#This Row],[Profit]]>0,"Hit","Flop") -> Flop | W7: {=_xlfn.IFS(IMDB4[[#This Row],[IMDb Score (1-10)]]>=8,"Excellent",IMDB4[[#This Row],[IMDb Score (1-10)]]>=7,"Good",IMDB4[[#This Row],[IMDb Score (1-10)]]>=5,"Average",TRUE,"Poor")} -> Average | X7: =IF(IMDB4[[#This Row],[Duration (min)]]<90,"Short",IF(IMDB4[[#This Row],[Duration (min)]]<=120,"Medium", "Long")) -> Medium
A8: The Amityville Horror | B8: 38591 | C8: =YEAR(IMDB4[[#This Row],[Release Date]]) -> 2005 | D8: =FLOOR(IMDB4[[#This Row],[Year]],10)&"s" -> 2000s | E8: Color | F8: Drama | G8: English | H8: USA | I8: R | J8: Jimmy Bennett | K8: Andrew Douglas | L8: 87000 | M8: 120797 | N8: 15 | O8: 0 | P8: 6 | Q8: 220 | R8: 90 | S8: 64255243 | T8: 19000000 | U8: =IMDB4[[#This Row],[Gross Revenue]]-IMDB4[[#This Row],[Budget]] -> 45255243 | V8: =IF(IMDB4[[#This Row],[Profit]]>0,"Hit","Flop") -> Hit | W8: {=_xlfn.IFS(IMDB4[[#This Row],[IMDb Score (1-10)]]>=8,"Excellent",IMDB4[[#This Row],[IMDb Score (1-10)]]>=7,"Good",IMDB4[[#This Row],[IMDb Score (1-10)]]>=5,"Average",TRUE,"Poor")} -> Average | X8: =IF(IMDB4[[#This Row],[Duration (min)]]<90,"Short",IF(IMDB4[[#This Row],[Duration (min)]]<=120,"Medium", "Long")) -> Medium
A9: Poseidon | B9: 38786 | C9: =YEAR(IMDB4[[#This Row],[Release Date]]) -> 2006 | D9: =FLOOR(IMDB4[[#This Row],[Year]],10)&"s" -> 2000s | E9: Color | F9: Action | G9: English | H9: USA | I9: PG-13 | J9: Jimmy Bennett | K9: Wolfgang Petersen | L9: 87000 | M9: 92456 | N9: 249 | O9: 0 | P9: 5.6 | Q9: 231 | R9: 98 | S9: 60655503 | T9: 160000000 | U9: =IMDB4[[#This Row],[Gross Revenue]]-IMDB4[[#This Row],[Budget]] -> -99344497 | V9: =IF(IMDB4[[#This Row],[Profit]]>0,"Hit","Flop") -> Flop | W9: {=_xlfn.IFS(IMDB4[[#This Row],[IMDb Score (1-10)]]>=8,"Excellent",IMDB4[[#This Row],[IMDb Score (1-10)]]>=7,"Good",IMDB4[[#This Row],[IMDb Score (1-10)]]>=5,"Average",TRUE,"Poor")} -> Average | X9: =IF(IMDB4[[#This Row],[Duration (min)]]<90,"Short",IF(IMDB4[[#This Row],[Duration (min)]]<=120,"Medium", "Long")) -> Medium
A10: Firewall | B10: 39027 | C10: =YEAR(IMDB4[[#This Row],[Release Date]]) -> 2006 | D10: =FLOOR(IMDB4[[#This Row],[Year]],10)&"s" -> 2000s | E10: Color | F10: Crime | G10: English | H10: USA | I10: PG-13 | J10: Jimmy Bennett | K10: Richard Loncraine | L10: 87000 | M10: 101383 | N10: 12 | O10: 773 | P10: 5.8 | Q10: 171 | R10: 105 | S10: 48745150 | T10: 50000000 | U10: =IMDB4[[#This Row],[Gross Revenue]]-IMDB4[[#This Row],[Budget]] -> -1254850 | V10: =IF(IMDB4[[#This Row],[Profit]]>0,"Hit","Flop") -> Flop | W10: {=_xlfn.IFS(IMDB4[[#This Row],[IMDb Score (1-10)]]>=8,"Excellent",IMDB4[[#This Row],[IMDb Score (1-10)]]>=7,"Good",IMDB4[[#This Row],[IMDb Score (1-10)]]>=5,"Average",TRUE,"Poor")} -> Average | X10: =IF(IMDB4[[#This Row],[Duration (min)]]<90,"Short",IF(IMDB4[[#This Row],[Duration (min)]]<=120,"Medium", "Long")) -> Medium | Z10: Rating | AA10: {=_xlfn.UNIQUE(H:H)} -> Country
A11: Hostage | B11: 38678 | C11: =YEAR(IMDB4[[#This Row],[Release Date]]) -> 2005 | D11: =FLOOR(IMDB4[[#This Row],[Year]],10)&"s" -> 2000s | E11: Color | F11: Action | G11: English | H11: USA | I11: R | J11: Jimmy Bennett | K11: Florent-Emilio Siri | L11: 87000 | M11: 103354 | N11: 17 | O11: 0 | P11: 6.6 | Q11: 152 | R11: 113 | S11: 34636443 | T11: 52000000 | U11: =IMDB4[[#This Row],[Gross Revenue]]-IMDB4[[#This Row],[Budget]] -> -17363557 | V11: =IF(IMDB4[[#This Row],[Profit]]>0,"Hit","Flop") -> Flop | W11: {=_xlfn.IFS(IMDB4[[#This Row],[IMDb Score (1-10)]]>=8,"Excellent",IMDB4[[#This Row],[IMDb Score (1-10)]]>=7,"Good",IMDB4[[#This Row],[IMDb Score (1-10)]]>=5,"Average",TRUE,"Poor")} -> Average | X11: =IF(IMDB4[[#This Row],[Duration (min)]]<90,"Short",IF(IMDB4[[#This Row],[Duration (min)]]<=120,"Medium", "Long")) -> Medium | Z11: =W2 -> Good | AA11: USA | AB11: =SUMIFS(U:U,H:H,AA11,W:W,Z11) -> 23714615563 | AE11: =SUMIF(IMDB4[Country],AA11,IMDB4[Profit]) -> 50991982137
A12: Shorts | B12: 39919 | C12: =YEAR(IMDB4[[#This Row],[Release Date]]) -> 2009 | D12: =FLOOR(IMDB4[[#This Row],[Year]],10)&"s" -> 2000s | E12: Color | F12: Comedy | G12: English | H12: USA | I12: PG | J12: Jimmy Bennett | K12: Robert Rodriguez | L12: 87000 | M12: 88422 | N12: 0 | O12: 431 | P12: 4.9 | Q12: 103 | R12: 89 | S12: 20916309 | T12: 40000000 | U12: =IMDB4[[#This Row],[Gross Revenue]]-IMDB4[[#This Row],[Budget]] -> -19083691 | V12: =IF(IMDB4[[#This Row],[Profit]]>0,"Hit","Flop") -> Flop | W12: {=_xlfn.IFS(IMDB4[[#This Row],[IMDb Score (1-10)]]>=8,"Excellent",IMDB4[[#This Row],[IMDb Score (1-10)]]>=7,"Good",IMDB4[[#This Row],[IMDb Score (1-10)]]>=5,"Average",TRUE,"Poor")} -> Poor | X12: =IF(IMDB4[[#This Row],[Duration (min)]]<90,"Short",IF(IMDB4[[#This Row],[Duration (min)]]<=120,"Medium", "Long")) -> Short | Z12: =W3 -> Average | AA12: Australia | AB12: =SUMIFS(U:U,H:H,AA12,W:W,Z12) -> -7042072
A13: Trucker | B13: 39619 | C13: =YEAR(IMDB4[[#This Row],[Release Date]]) -> 2008 | D13: =FLOOR(IMDB4[[#This Row],[Year]],10)&"s" -> 2000s | E13: Color | F13: Drama | G13: English | H13: USA | I13: R | J13: Jimmy Bennett | K13: James Mottern | L13: 87000 | M13: 89263 | N13: 7 | O13: 371 | P13: 6.7 | Q13: 46 | R13: 90 | S13: 52166 | T13: 2000000 | U13: =IMDB4[[#This Row],[Gross Revenue]]-IMDB4[[#This Row],[Budget]] -> -1947834 | V13: =IF(IMDB4[[#This Row],[Profit]]>0,"Hit","Flop") -> Flop | W13: {=_xlfn.IFS(IMDB4[[#This Row],[IMDb Score (1-10)]]>=8,"Excellent",IMDB4[[#This Row],[IMDb Score (1-10)]]>=7,"Good",IMDB4[[#This Row],[IMDb Score (1-10)]]>=5,"Average",TRUE,"Poor")} -> Average | X13: =IF(IMDB4[[#This Row],[Duration (min)]]<90,"Short",IF(IMDB4[[#This Row],[Duration (min)]]<=120,"Medium", "Long")) -> Medium | Z13: =W4 -> Average | AA13: UK | AB13: =SUMIFS(U:U,H:H,AA13,W:W,Z13) -> -999235212
A14: The Grace Card | B14: 40498 | C14: =YEAR(IMDB4[[#This Row],[Release Date]]) -> 2010 | D14: =FLOOR(IMDB4[[#This Row],[Year]],10)&"s" -> 2010s | E14: Color | F14: Drama | G14: English | H14: USA | I14: PG-13 | J14: Michael Joiner | K14: David G. Evans | L14: 77000 | M14: 77046 | N14: 0 | O14: 0 | P14: 6.4 | Q14: 25 | R14: 101 | S14: 2428241 | T14: 200000 | U14: =IMDB4[[#This Row],[Gross Revenue]]-IMDB4[[#This Row],[Budget]] -> 2228241 | V14: =IF(IMDB4[[#This Row],[Profit]]>0,"Hit","Flop") -> Hit | W14: {=_xlfn.IFS(IMDB4[[#This Row],[IMDb Score (1-10)]]>=8,"Excellent",IMDB4[[#This Row],[IMDb Score (1-10)]]>=7,"Good",IMDB4[[#This Row],[IMDb Score (1-10)]]>=5,"Average",TRUE,"Poor")} -> Average | X14: =IF(IMDB4[[#This Row],[Duration (min)]]<90,"Short",IF(IMDB4[[#This Row],[Duration (min)]]<=120,"Medium", "Long")) -> Medium | Z14: =W5 -> Average | AA14: France | AB14: =SUMIFS(U:U,H:H,AA14,W:W,Z14) -> -1031277560
A15: Night at the Museum | B15: 38835 | C15: =YEAR(IMDB4[[#This Row],[Release Date]]) -> 2006 | D15: =FLOOR(IMDB4[[#This Row],[Year]],10)&"s" -> 2000s | E15: Color | F15: Action | G15: English | H15: USA | I15: PG | J15: Robin Williams | K15: Shawn Levy | L15: 49000 | M15: 55486 | N15: 189 | O15: 3000 | P15: 6.4 | Q15: 179 | R15: 108 | S15: 250863268 | T15: 110000000 | U15: =IMDB4[[#This Row],[Gross Revenue]]-IMDB4[[#This Row],[Budget]] -> 140863268 | V15: =IF(IMDB4[[#This Row],[Profit]]>0,"Hit","Flop") -> Hit | W15: {=_xlfn.IFS(IMDB4[[#This Row],[IMDb Score (1-10)]]>=8,"Excellent",IMDB4[[#This Row],[IMDb Score (1-10)]]>=7,"Good",IMDB4[[#This Row],[IMDb Score (1-10)]]>=5,"Average",TRUE,"Poor")} -> Average | X15: =IF(IMDB4[[#This Row],[Duration (min)]]<90,"Short",IF(IMDB4[[#This Row],[Duration (min)]]<=120,"Medium", "Long")) -> Medium | Z15: =W6 -> Average | AA15: Spain | AB15: =SUMIFS(U:U,H:H,AA15,W:W,Z15) -> -133682841
A16: Mrs. Doubtfire | B16: 34227 | C16: =YEAR(IMDB4[[#This Row],[Release Date]]) -> 1993 | D16: =FLOOR(IMDB4[[#This Row],[Year]],10)&"s" -> 1990s | E16: Color | F16: Comedy | G16: English | H16: USA | I16: PG-13 | J16: Robin Williams | K16: Chris Columbus | L16: 49000 | M16: 52201 | N16: 0 | O16: 0 | P16: 6.9 | Q16: 57 | R16: 125 | S16: 219200000 | T16: 25000000 | U16: =IMDB4[[#This Row],[Gross Revenue]]-IMDB4[[#This Row],[Budget]] -> 194200000 | V16: =IF(IMDB4[[#This Row],[Profit]]>0,"Hit","Flop") -> Hit | W16: {=_xlfn.IFS(IMDB4[[#This Row],[IMDb Score (1-10)]]>=8,"Excellent",IMDB4[[#This Row],[IMDb Score (1-10)]]>=7,"Good",IMDB4[[#This Row],[IMDb Score (1-10)]]>=5,"Average",TRUE,"Poor")} -> Average | X16: =IF(IMDB4[[#This Row],[Duration (min)]]<90,"Short",IF(IMDB4[[#This Row],[Duration (min)]]<=120,"Medium", "Long")) -> Long | Z16: =W7 -> Average | AA16: Canada | AB16: =SUMIFS(U:U,H:H,AA16,W:W,Z16) -> 185406739
A17: Aladdin | B17: 33910 | C17: =YEAR(IMDB4[[#This Row],[Release Date]]) -> 1992 | D17: =FLOOR(IMDB4[[#This Row],[Year]],10)&"s" -> 1990s | E17: Color | F17: Adventure | G17: English | H17: USA | I17: G | J17: Robin Williams | K17: Ron Clements | L17: 49000 | M17: 52970 | N17: 63 | O17: 0 | P17: 8 | Q17: 124 | R17: 90 | S17: 217350219 | T17: 28000000 | U17: =IMDB4[[#This Row],[Gross Revenue]]-IMDB4[[#This Row],[Budget]] -> 189350219 | V17: =IF(IMDB4[[#This Row],[Profit]]>0,"Hit","Flop") -> Hit | W17: {=_xlfn.IFS(IMDB4[[#This Row],[IMDb Score (1-10)]]>=8,"Excellent",IMDB4[[#This Row],[IMDb Score (1-10)]]>=7,"Good",IMDB4[[#This Row],[IMDb Score (1-10)]]>=5,"Average",TRUE,"Poor")} -> Excellent | X17: =IF(IMDB4[[#This Row],[Duration (min)]]<90,"Short",IF(IMDB4[[#This Row],[Duration (min)]]<=120,"Medium", "Long")) -> Medium | Z17: =W8 -> Average | AA17: Denmark | AB17: =SUMIFS(U:U,H:H,AA17,W:W,Z17) -> -37699201
A18: Happy Feet | B18: 38758 | C18: =YEAR(IMDB4[[#This Row],[Release Date]]) -> 2006 | D18: =FLOOR(IMDB4[[#This Row],[Year]],10)&"s" -> 2000s | E18: Color | F18: Animation | G18: English | H18: USA | I18: PG | J18: Robin Williams | K18: George Miller | L18: 49000 | M18: 70996 | N18: 750 | O18: 0 | P18: 6.5 | Q18: 206 | R18: 108 | S18: 197992827 | T18: 100000000 | U18: =IMDB4[[#This Row],[Gross Revenue]]-IMDB4[[#This Row],[Budget]] -> 97992827 | V18: =IF(IMDB4[[#This Row],[Profit]]>0,"Hit","Flop") -> Hit | W18: {=_xlfn.IFS(IMDB4[[#This Row],[IMDb Score (1-10)]]>=8,"Excellent",IMDB4[[#This Row],[IMDb Score (1-10)]]>=7,"Good",IMDB4[[#This Row],[IMDb Score (1-10)]]>=5,"Average",TRUE,"Poor")} -> Average | X18: =IF(IMDB4[[#This Row],[Duration (min)]]<90,"Short",IF(IMDB4[[#This Row],[Duration (min)]]<=120,"Medium", "Long")) -> Medium | Z18: =W9 -> Average | AA18: Belgium | AB18: =SUMIFS(U:U,H:H,AA18,W:W,Z18) -> -33995909
A19: Night at the Museum: Battle of the Smithsonian | B19: 40011 | C19: =YEAR(IMDB4[[#This Row],[Release Date]]) -> 2009 | D19: =FLOOR(IMDB4[[#This Row],[Year]],10)&"s" -> 2000s | E19: Color | F19: Adventure | G19: English | H19: USA | I19: PG | J19: Robin Williams | K19: Shawn Levy | L19: 49000 | M19: 54039 | N19: 189 | O19: 2000 | P19: 5.9 | Q19: 185 | R19: 105 | S19: 177243721 | T19: 150000000 | U19: =IMDB4[[#This Row],[Gross Revenue]]-IMDB4[[#This Row],[Budget]] -> 27243721 | V19: =IF(IMDB4[[#This Row],[Profit]]>0,"Hit","Flop") -> Hit | W19: {=_xlfn.IFS(IMDB4[[#This Row],[IMDb Score (1-10)]]>=8,"Excellent",IMDB4[[#This Row],[IMDb Score (1-10)]]>=7,"Good",IMDB4[[#This Row],[IMDb Score (1-10)]]>=5,"Average",TRUE,"Poor")} -> Average | X19: =IF(IMDB4[[#This Row],[Duration (min)]]<90,"Short",IF(IMDB4[[#This Row],[Duration (min)]]<=120,"Medium", "Long")) -> Medium | Z19: =W10 -> Average | AA19: Germany | AB19: =SUMIFS(U:U,H:H,AA19,W:W,Z19) -> -155335898
A20: Good Will Hunting | B20: 35562 | C20: =YEAR(IMDB4[[#This Row],[Release Date]]) -> 1997 | D20: =FLOOR(IMDB4[[#This Row],[Year]],10)&"s" -> 1990s | E20: Color | F20: Drama | G20: English | H20: USA | I20: R | J20: Robin Williams | K20: Gus Van Sant | L20: 49000 | M20: 63710 | N20: 835 | O20: 31000 | P20: 8.3 | Q20: 161 | R20: 126 | S20: 138339411 | T20: 10000000 | U20: =IMDB4[[#This Row],[Gross Revenue]]-IMDB4[[#This Row],[Budget]] -> 128339411 | V20: =IF(IMDB4[[#This Row],[Profit]]>0,"Hit","Flop") -> Hit | W20: {=_xlfn.IFS(IMDB4[[#This Row],[IMDb Score (1-10)]]>=8,"Excellent",IMDB4[[#This Row],[IMDb Score (1-10)]]>=7,"Good",IMDB4[[#This Row],[IMDb Score (1-10)]]>=5,"Average",TRUE,"Poor")} -> Excellent | X20: =IF(IMDB4[[#This Row],[Duration (min)]]<90,"Short",IF(IMDB4[[#This Row],[Duration (min)]]<=120,"Medium", "Long")) -> Long | Z20: =W11 -> Average | AA20: Japan | AB20: =SUMIFS(U:U,H:H,AA20,W:W,Z20) -> -3060904553
A21: Patch Adams | B21: 35803 | C21: =YEAR(IMDB4[[#This Row],[Release Date]]) -> 1998 | D21: =FLOOR(IMDB4[[#This Row],[Year]],10)&"s" -> 1990s | E21: Color | F21: Biography | G21: English | H21: USA | I21: PG-13 | J21: Robin Williams | K21: Tom Shadyac | L21: 49000 | M21: 74382 | N21: 293 | O21: 0 | P21: 6.7 | Q21: 55 | R21: 115 | S21: 135014968 | T21: 50000000 | U21: =IMDB4[[#This Row],[Gross Revenue]]-IMDB4[[#This Row],[Budget]] -> 85014968 | V21: =IF(IMDB4[[#This Row],[Profit]]>0,"Hit","Flop") -> Hit | W21: {=_xlfn.IFS(IMDB4[[#This Row],[IMDb Score (1-10)]]>=8,"Excellent",IMDB4[[#This Row],[IMDb Score (1-10)]]>=7,"Good",IMDB4[[#This Row],[IMDb Score (1-10)]]>=5,"Average",TRUE,"Poor")} -> Average | X21: =IF(IMDB4[[#This Row],[Duration (min)]]<90,"Short",IF(IMDB4[[#This Row],[Duration (min)]]<=120,"Medium", "Long")) -> Medium | Z21: =W12 -> Poor | AA21: Czech Republic | AB21: =SUMIFS(U:U,H:H,AA21,W:W,Z21) -> 0
A22: Good Morning, Vietnam | B22: 31858 | C22: =YEAR(IMDB4[[#This Row],[Release Date]]) -> 1987 | D22: =FLOOR(IMDB4[[#This Row],[Year]],10)&"s" -> 1980s | E22: Color | F22: Biography | G22: English | H22: USA | I22: R | J22: Robin Williams | K22: Barry Levinson | L22: 49000 | M22: 50141 | N22: 272 | O22: 0 | P22: 7.3 | Q22: 62 | R22: 121 | S22: 123922370 | T22: 13000000 | U22: =IMDB4[[#This Row],[Gross Revenue]]-IMDB4[[#This Row],[Budget]] -> 110922370 | V22: =IF(IMDB4[[#This Row],[Profit]]>0,"Hit","Flop") -> Hit | W22: {=_xlfn.IFS(IMDB4[[#This Row],[IMDb Score (1-10)]]>=8,"Excellent",IMDB4[[#This Row],[IMDb Score (1-10)]]>=7,"Good",IMDB4[[#This Row],[IMDb Score (1-10)]]>=5,"Average",TRUE,"Poor")} -> Good | X22: =IF(IMDB4[[#This Row],[Duration (min)]]<90,"Short",IF(IMDB4[[#This Row],[Duration (min)]]<=120,"Medium", "Long")) -> Long | Z22: =W13 -> Average | AA22: China | AB22: =SUMIFS(U:U,H:H,AA22,W:W,Z22) -> -171656361
A23: Hook | B23: 33368 | C23: =YEAR(IMDB4[[#This Row],[Release Date]]) -> 1991 | D23: =FLOOR(IMDB4[[#This Row],[Year]],10)&"s" -> 1990s | E23: Color | F23: Adventure | G23: English | H23: USA | I23: PG | J23: Robin Williams | K23: Steven Spielberg | L23: 49000 | M23: 64259 | N23: 14000 | O23: 13000 | P23: 6.7 | Q23: 75 | R23: 142 | S23: 119654900 | T23: 70000000 | U23: =IMDB4[[#This Row],[Gross Revenue]]-IMDB4[[#This Row],[Budget]] -> 49654900 | V23: =IF(IMDB4[[#This Row],[Profit]]>0,"Hit","Flop") -> Hit | W23: {=_xlfn.IFS(IMDB4[[#This Row],[IMDb Score (1-10)]]>=8,"Excellent",IMDB4[[#This Row],[IMDb Score (1-10)]]>=7,"Good",IMDB4[[#This Row],[IMDb Score (1-10)]]>=5,"Average",TRUE,"Poor")} -> Average | X23: =IF(IMDB4[[#This Row],[Duration (min)]]<90,"Short",IF(IMDB4[[#This Row],[Duration (min)]]<=120,"Medium", "Long")) -> Long | Z23: =W14 -> Average | AA23: Italy | AB23: =SUMIFS(U:U,H:H,AA23,W:W,Z23) -> -61328888
... A56: Rango | B56: 40797 | C56: =YEAR(IMDB4[[#This Row],[Release Date]]) -> 2011 | D56: =FLOOR(IMDB4[[#This Row],[Year]],10)&"s" -> 2010s | E56: Color | F56: Adventure | G56: English | H56: USA | I56: PG | J56: Johnny Depp | K56: Gore Verbinski | L56: 40000 | M56: 43291 | N56: 563 | O56: 26000 | P56: 7.2 | Q56: 362 | R56: 107 | S56: 123207194 | T56: 135000000 | U56: =IMDB4[[#This Row],[Gross Revenue]]-IMDB4[[#This Row],[Budget]] -> -11792806 | V56: =IF(IMDB4[[#This Row],[Profit]]>0,"Hit","Flop") -> Flop | W56: {=_xlfn.IFS(IMDB4[[#This Row],[IMDb Score (1-10)]]>=8,"Excellent",IMDB4[[#This Row],[IMDb Score (1-10)]]>=7,"Good",IMDB4[[#This Row],[IMDb Score (1-10)]]>=5,"Average",TRUE,"Poor")} -> Good | X56: =IF(IMDB4[[#This Row],[Duration (min)]]<90,"Short",IF(IMDB4[[#This Row],[Duration (min)]]<=120,"Medium", "Long")) -> Medium | Z56: =W47 -> Average | AA56: Philippines | AB56: =SUMIFS(U:U,H:H,AA56,W:W,Z56) -> 63071
A57: Public Enemies | B57: 40147 | C57: =YEAR(IMDB4[[#This Row],[Release Date]]) -> 2009 | D57: =FLOOR(IMDB4[[#This Row],[Year]],10)&"s" -> 2000s | E57: Color | F57: Biography | G57: English | H57: USA | I57: R | J57: Johnny Depp | K57: Michael Mann | L57: 40000 | M57: 64599 | N57: 0 | O57: 0 | P57: 7 | Q57: 357 | R57: 140 | S57: 97030725 | T57: 100000000 | U57: =IMDB4[[#This Row],[Gross Revenue]]-IMDB4[[#This Row],[Budget]] -> -2969275 | V57: =IF(IMDB4[[#This Row],[Profit]]>0,"Hit","Flop") -> Flop | W57: {=_xlfn.IFS(IMDB4[[#This Row],[IMDb Score (1-10)]]>=8,"Excellent",IMDB4[[#This Row],[IMDb Score (1-10)]]>=7,"Good",IMDB4[[#This Row],[IMDb Score (1-10)]]>=5,"Average",TRUE,"Poor")} -> Good | X57: =IF(IMDB4[[#This Row],[Duration (min)]]<90,"Short",IF(IMDB4[[#This Row],[Duration (min)]]<=120,"Medium", "Long")) -> Long | Z57: =W48 -> Good | AA57: 0 | AB57: =SUMIFS(U:U,H:H,AA57,W:W,Z57) -> 0
A58: The Lone Ranger | B58: 41630 | C58: =YEAR(IMDB4[[#This Row],[Release Date]]) -> 2013 | D58: =FLOOR(IMDB4[[#This Row],[Year]],10)&"s" -> 2010s | E58: Color | F58: Action | G58: English | H58: USA | I58: PG-13 | J58: Johnny Depp | K58: Gore Verbinski | L58: 40000 | M58: 45757 | N58: 563 | O58: 48000 | P58: 6.5 | Q58: 450 | R58: 150 | S58: 89289910 | T58: 215000000 | U58: =IMDB4[[#This Row],[Gross Revenue]]-IMDB4[[#This Row],[Budget]] -> -125710090 | V58: =IF(IMDB4[[#This Row],[Profit]]>0,"Hit","Flop") -> Flop | W58: {=_xlfn.IFS(IMDB4[[#This Row],[IMDb Score (1-10)]]>=8,"Excellent",IMDB4[[#This Row],[IMDb Score (1-10)]]>=7,"Good",IMDB4[[#This Row],[IMDb Score (1-10)]]>=5,"Average",TRUE,"Poor")} -> Average | X58: =IF(IMDB4[[#This Row],[Duration (min)]]<90,"Short",IF(IMDB4[[#This Row],[Duration (min)]]<=120,"Medium", "Long")) -> Long
A59: Dark Shadows | B59: 40981 | C59: =YEAR(IMDB4[[#This Row],[Release Date]]) -> 2012 | D59: =FLOOR(IMDB4[[#This Row],[Year]],10)&"s" -> 2010s | E59: Color | F59: Comedy | G59: English | H59: USA | I59: PG-13 | J59: Johnny Depp | K59: Tim Burton | L59: 40000 | M59: 80849 | N59: 13000 | O59: 82000 | P59: 6.2 | Q59: 526 | R59: 113 | S59: 79711678 | T59: 100000000 | U59: =IMDB4[[#This Row],[Gross Revenue]]-IMDB4[[#This Row],[Budget]] -> -20288322 | V59: =IF(IMDB4[[#This Row],[Profit]]>0,"Hit","Flop") -> Flop | W59: {=_xlfn.IFS(IMDB4[[#This Row],[IMDb Score (1-10)]]>=8,"Excellent",IMDB4[[#This Row],[IMDb Score (1-10)]]>=7,"Good",IMDB4[[#This Row],[IMDb Score (1-10)]]>=5,"Average",TRUE,"Poor")} -> Average | X59: =IF(IMDB4[[#This Row],[Duration (min)]]<90,"Short",IF(IMDB4[[#This Row],[Duration (min)]]<=120,"Medium", "Long")) -> Medium
A60: The Tourist | B60: 40538 | C60: =YEAR(IMDB4[[#This Row],[Release Date]]) -> 2010 | D60: =FLOOR(IMDB4[[#This Row],[Year]],10)&"s" -> 2010s | E60: Color | F60: Action | G60: English | H60: USA | I60: PG-13 | J60: Johnny Depp | K60: Florian Henckel von Donnersmarck | L60: 40000 | M60: 55175 | N60: 207 | O60: 25000 | P60: 6 | Q60: 321 | R60: 103 | S60: 67631157 | T60: 100000000 | U60: =IMDB4[[#This Row],[Gross Revenue]]-IMDB4[[#This Row],[Budget]] -> -32368843 | V60: =IF(IMDB4[[#This Row],[Profit]]>0,"Hit","Flop") -> Flop | W60: {=_xlfn.IFS(IMDB4[[#This Row],[IMDb Score (1-10)]]>=8,"Excellent",IMDB4[[#This Row],[IMDb Score (1-10)]]>=7,"Good",IMDB4[[#This Row],[IMDb Score (1-10)]]>=5,"Average",TRUE,"Poor")} -> Average | X60: =IF(IMDB4[[#This Row],[Duration (min)]]<90,"Short",IF(IMDB4[[#This Row],[Duration (min)]]<=120,"Medium", "Long")) -> Medium
A61: Black Mass | B61: 42115 | C61: =YEAR(IMDB4[[#This Row],[Release Date]]) -> 2015 | D61: =FLOOR(IMDB4[[#This Row],[Year]],10)&"s" -> 2010s | E61: Color | F61: Biography | G61: English | H61: USA | I61: R | J61: Johnny Depp | K61: Scott Cooper | L61: 40000 | M61: 63769 | N61: 108 | O61: 44000 | P61: 7 | Q61: 391 | R61: 123 | S61: 62563543 | T61: 53000000 | U61: =IMDB4[[#This Row],[Gross Revenue]]-IMDB4[[#This Row],[Budget]] -> 9563543 | V61: =IF(IMDB4[[#This Row],[Profit]]>0,"Hit","Flop") -> Hit | W61: {=_xlfn.IFS(IMDB4[[#This Row],[IMDb Score (1-10)]]>=8,"Excellent",IMDB4[[#This Row],[IMDb Score (1-10)]]>=7,"Good",IMDB4[[#This Row],[IMDb Score (1-10)]]>=5,"Average",TRUE,"Poor")} -> Good | X61: =IF(IMDB4[[#This Row],[Duration (min)]]<90,"Short",IF(IMDB4[[#This Row],[Duration (min)]]<=120,"Medium", "Long")) -> Long
A62: Edward Scissorhands | B62: 33232 | C62: =YEAR(IMDB4[[#This Row],[Release Date]]) -> 1990 | D62: =FLOOR(IMDB4[[#This Row],[Year]],10)&"s" -> 1990s | E62: Color | F62: Fantasy | G62: English | H62: USA | I62: PG-13 | J62: Johnny Depp | K62: Tim Burton | L62: 40000 | M62: 42330 | N62: 13000 | O62: 16000 | P62: 7.9 | Q62: 111 | R62: 105 | S62: 56362352 | T62: 20000000 | U62: =IMDB4[[#This Row],[Gross Revenue]]-IMDB4[[#This Row],[Budget]] -> 36362352 | V62: =IF(IMDB4[[#This Row],[Profit]]>0,"Hit","Flop") -> Hit | W62: {=_xlfn.IFS(IMDB4[[#This Row],[IMDb Score (1-10)]]>=8,"Excellent",IMDB4[[#This Row],[IMDb Score (1-10)]]>=7,"Good",IMDB4[[#This Row],[IMDb Score (1-10)]]>=5,"Average",TRUE,"Poor")} -> Good | X62: =IF(IMDB4[[#This Row],[Duration (min)]]<90,"Short",IF(IMDB4[[#This Row],[Duration (min)]]<=120,"Medium", "Long")) -> Medium
A63: Once Upon a Time in Mexico | B63: 37726 | C63: =YEAR(IMDB4[[#This Row],[Release Date]]) -> 2003 | D63: =FLOOR(IMDB4[[#This Row],[Year]],10)&"s" -> 2000s | E63: Color | F63: Action | G63: English | H63: USA | I63: R | J63: Johnny Depp | K63: Robert Rodriguez | L63: 40000 | M63: 46186 | N63: 0 | O63: 0 | P63: 6.4 | Q63: 178 | R63: 102 | S63: 55845943 | T63: 29000000 | U63: =IMDB4[[#This Row],[Gross Revenue]]-IMDB4[[#This Row],[Budget]] -> 26845943 | V63: =IF(IMDB4[[#This Row],[Profit]]>0,"Hit","Flop") -> Hit | W63: {=_xlfn.IFS(IMDB4[[#This Row],[IMDb Score (1-10)]]>=8,"Excellent",IMDB4[[#This Row],[IMDb Score (1-10)]]>=7,"Good",IMDB4[[#This Row],[IMDb Score (1-10)]]>=5,"Average",TRUE,"Poor")} -> Average | X63: =IF(IMDB4[[#This Row],[Duration (min)]]<90,"Short",IF(IMDB4[[#This Row],[Duration (min)]]<=120,"Medium", "Long")) -> Medium
A64: Corpse Bride | B64: 38672 | C64: =YEAR(IMDB4[[#This Row],[Release Date]]) -> 2005 | D64: =FLOOR(IMDB4[[#This Row],[Year]],10)&"s" -> 2000s | E64: Color | F64: Animation | G64: English | H64: USA | I64: PG | J64: Johnny Depp | K64: Tim Burton | L64: 40000 | M64: 60683 | N64: 13000 | O64: 0 | P64: 7.4 | Q64: 267 | R64: 77 | S64: 53337608 | T64: 40000000 | U64: =IMDB4[[#This Row],[Gross Revenue]]-IMDB4[[#This Row],[Budget]] -> 13337608 | V64: =IF(IMDB4[[#This Row],[Profit]]>0,"Hit","Flop") -> Hit | W64: {=_xlfn.IFS(IMDB4[[#This Row],[IMDb Score (1-10)]]>=8,"Excellent",IMDB4[[#This Row],[IMDb Score (1-10)]]>=7,"Good",IMDB4[[#This Row],[IMDb Score (1-10)]]>=5,"Average",TRUE,"Poor")} -> Good | X64: =IF(IMDB4[[#This Row],[Duration (min)]]<90,"Short",IF(IMDB4[[#This Row],[Duration (min)]]<=120,"Medium", "Long")) -> Short
A65: Blow | B65: 37071 | C65: =YEAR(IMDB4[[#This Row],[Release Date]]) -> 2001 | D65: =FLOOR(IMDB4[[#This Row],[Year]],10)&"s" -> 2000s | E65: Color | F65: Biography | G65: English | H65: USA | I65: R | J65: Johnny Depp | K65: Ted Demme | L65: 40000 | M65: 43453 | N65: 47 | O65: 13000 | P65: 7.6 | Q65: 147 | R65: 124 | S65: 52937130 | T65: 30000000 | U65: =IMDB4[[#This Row],[Gross Revenue]]-IMDB4[[#This Row],[Budget]] -> 22937130 | V65: =IF(IMDB4[[#This Row],[Profit]]>0,"Hit","Flop") -> Hit | W65: {=_xlfn.IFS(IMDB4[[#This Row],[IMDb Score (1-10)]]>=8,"Excellent",IMDB4[[#This Row],[IMDb Score (1-10)]]>=7,"Good",IMDB4[[#This Row],[IMDb Score (1-10)]]>=5,"Average",TRUE,"Poor")} -> Good | X65: =IF(IMDB4[[#This Row],[Duration (min)]]<90,"Short",IF(IMDB4[[#This Row],[Duration (min)]]<=120,"Medium", "Long")) -> Long
A66: Finding Neverland | B66: 38233 | C66: =YEAR(IMDB4[[#This Row],[Release Date]]) -> 2004 | D66: =FLOOR(IMDB4[[#This Row],[Year]],10)&"s" -> 2000s | E66: Color | F66: Biography | G66: English | H66: USA | I66: PG | J66: Johnny Depp | K66: Marc Forster | L66: 40000 | M66: 58823 | N66: 395 | O66: 0 | P66: 7.8 | Q66: 226 | R66: 101 | S66: 51676606 | T66: 25000000 | U66: =IMDB4[[#This Row],[Gross Revenue]]-IMDB4[[#This Row],[Budget]] -> 26676606 | V66: =IF(IMDB4[[#This Row],[Profit]]>0,"Hit","Flop") -> Hit | W66: {=_xlfn.IFS(IMDB4[[#This Row],[IMDb Score (1-10)]]>=8,"Excellent",IMDB4[[#This Row],[IMDb Score (1-10)]]>=7,"Good",IMDB4[[#This Row],[IMDb Score (1-10)]]>=5,"Average",TRUE,"Poor")} -> Good | X66: =IF(IMDB4[[#This Row],[Duration (min)]]<90,"Short",IF(IMDB4[[#This Row],[Duration (min)]]<=120,"Medium", "Long")) -> Medium
A67: Secret Window | B67: 38330 | C67: =YEAR(IMDB4[[#This Row],[Release Date]]) -> 2004 | D67: =FLOOR(IMDB4[[#This Row],[Year]],10)&"s" -> 2000s | E67: Color | F67: Mystery | G67: English | H67: USA | I67: PG-13 | J67: Johnny Depp | K67: David Koepp | L67: 40000 | M67: 41293 | N67: 192 | O67: 0 | P67: 6.6 | Q67: 195 | R67: 96 | S67: 47781388 | T67: 40000000 | U67: =IMDB4[[#This Row],[Gross Revenue]]-IMDB4[[#This Row],[Budget]] -> 7781388 | V67: =IF(IMDB4[[#This Row],[Profit]]>0,"Hit","Flop") -> Hit | W67: {=_xlfn.IFS(IMDB4[[#This Row],[IMDb Score (1-10)]]>=8,"Excellent",IMDB4[[#This Row],[IMDb Score (1-10)]]>=7,"Good",IMDB4[[#This Row],[IMDb Score (1-10)]]>=5,"Average",TRUE,"Poor")} -> Average | X67: =IF(IMDB4[[#This Row],[Duration (min)]]<90,"Short",IF(IMDB4[[#This Row],[Duration (min)]]<=120,"Medium", "Long")) -> Medium
A68: Donnie Brasco | B68: 35445 | C68: =YEAR(IMDB4[[#This Row],[Release Date]]) -> 1997 | D68: =FLOOR(IMDB4[[#This Row],[Year]],10)&"s" -> 1990s | E68: Color | F68: Biography | G68: English | H68: USA | I68: R | J68: Johnny Depp | K68: Mike Newell | L68: 40000 | M68: 56014 | N68: 179 | O68: 0 | P68: 7.8 | Q68: 117 | R68: 147 | S68: 41954997 | T68: 35000000 | U68: =IMDB4[[#This Row],[Gross Revenue]]-IMDB4[[#This Row],[Budget]] -> 6954997 | V68: =IF(IMDB4[[#This Row],[Profit]]>0,"Hit","Flop") -> Hit | W68: {=_xlfn.IFS(IMDB4[[#This Row],[IMDb Score (1-10)]]>=8,"Excellent",IMDB4[[#This Row],[IMDb Score (1-10)]]>=7,"Good",IMDB4[[#This Row],[IMDb Score (1-10)]]>=5,"Average",TRUE,"Poor")} -> Good | X68: =IF(IMDB4[[#This Row],[Duration (min)]]<90,"Short",IF(IMDB4[[#This Row],[Duration (min)]]<=120,"Medium", "Long")) -> Long
A69: Freddy's Dead: The Final Nightmare | B69: 33506 | C69: =YEAR(IMDB4[[#This Row],[Release Date]]) -> 1991 | D69: =FLOOR(IMDB4[[#This Row],[Year]],10)&"s" -> 1990s | E69: Color | F69: Comedy | G69: English | H69: USA | I69: R | J69: Johnny Depp | K69: Rachel Talalay | L69: 40000 | M69: 42002 | N69: 54 | O69: 963 | P69: 4.9 | Q69: 91 | R69: 93 | S69: 34872293 | T69: 8500000 | U69: =IMDB4[[#This Row],[Gross Revenue]]-IMDB4[[#This Row],[Budget]] -> 26372293 | V69: =IF(IMDB4[[#This Row],[Profit]]>0,"Hit","Flop") -> Hit | W69: {=_xlfn.IFS(IMDB4[[#This Row],[IMDb Score (1-10)]]>=8,"Excellent",IMDB4[[#This Row],[IMDb Score (1-10)]]>=7,"Good",IMDB4[[#This Row],[IMDb Score (1-10)]]>=5,"Average",TRUE,"Poor")} -> Poor | X69: =IF(IMDB4[[#This Row],[Duration (min)]]<90,"Short",IF(IMDB4[[#This Row],[Duration (min)]]<=120,"Medium", "Long")) -> Medium
... A3727: Antarctic Edge: 70Â° South | B3727: 42057 | C3727: =YEAR(IMDB4[[#This Row],[Release Date]]) -> 2015 | D3727: =FLOOR(IMDB4[[#This Row],[Year]],10)&"s" -> 2010s | E3727: Color | F3727: Adventure | G3727: English | H3727: USA | I3727: Not Rated | J3727: Naderev Sano | K3727: Dena Seidel | L3727: 0 | M3727: 0 | N3727: 0 | O3727: 215 | P3727: 7 | Q3727: 5 | R3727: 72 | S3727: 4914 | T3727: 150000 | U3727: =IMDB4[[#This Row],[Gross Revenue]]-IMDB4[[#This Row],[Budget]] -> -145086 | V3727: =IF(IMDB4[[#This Row],[Profit]]>0,"Hit","Flop") -> Flop | W3727: {=_xlfn.IFS(IMDB4[[#This Row],[IMDb Score (1-10)]]>=8,"Excellent",IMDB4[[#This Row],[IMDb Score (1-10)]]>=7,"Good",IMDB4[[#This Row],[IMDb Score (1-10)]]>=5,"Average",TRUE,"Poor")} -> Good | X3727: =IF(IMDB4[[#This Row],[Duration (min)]]<90,"Short",IF(IMDB4[[#This Row],[Duration (min)]]<=120,"Medium", "Long")) -> Short

Sheet Formula_Analysis
A1: Total Number of Movies | B1: =COUNTA(IMDB4[Title]) -> 3726
A2: Average IMDb Score | B2: =AVERAGE(IMDB4[IMDb Score (1-10)]) -> 6.463956
A3: Total Gross Revenue | B3: =SUM(IMDB4[Gross Revenue]) -> 185291371640
A4: Total Profit | B4: =SUM(IMDB4[Profit]) -> 20013582391
A6: Top 10 Movies by IMDb Score
A7: {=_xlfn._xlws.SORT(IMDB4[[Title]:[IMDb Score (1-10)]],16,-1)} -> The Shawshank Redemption | B7: 34427 | C7: 1994 | D7: 1990s | E7: Color | F7: Crime | G7: English | H7: USA | I7: R | J7: Morgan Freeman | K7: Frank Darabont | L7: 11000 | M7: 13495 | N7: 0 | O7: 108000 | P7: 9.3 | R7: {=_xlfn.TAKE(_xlfn.ANCHORARRAY(A7),10)} -> The Shawshank Redemption | S7: 34427 | T7: 1994 | U7: 1990s | V7: Color | W7: Crime | X7: English | Y7: USA | Z7: R | AA7: Morgan Freeman | AB7: Frank Darabont | AC7: 11000 | AD7: 13495 | AE7: 0 | AF7: 108000 | AG7: 9.3
A8: The Godfather | B8: 26351 | C8: 1972 | D8: 1970s | E8: Color | F8: Crime | G8: English | H8: USA | I8: R | J8: Al Pacino | K8: Francis Ford Coppola | L8: 14000 | M8: 28122 | N8: 0 | O8: 43000 | P8: 9.2 | R8: The Godfather | S8: 26351 | T8: 1972 | U8: 1970s | V8: Color | W8: Crime | X8: English | Y8: USA | Z8: R | AA8: Al Pacino | AB8: Francis Ford Coppola | AC8: 14000 | AD8: 28122 | AE8: 0 | AF8: 43000 | AG8: 9.2
A9: The Dark Knight | B9: 39577 | C9: 2008 | D9: 2000s | E9: Color | F9: Action | G9: English | H9: USA | I9: PG-13 | J9: Christian Bale | K9: Christopher Nolan | L9: 23000 | M9: 57802 | N9: 22000 | O9: 37000 | P9: 9 | R9: The Dark Knight | S9: 39577 | T9: 2008 | U9: 2000s | V9: Color | W9: Action | X9: English | Y9: USA | Z9: PG-13 | AA9: Christian Bale | AB9: Christopher Nolan | AC9: 23000 | AD9: 57802 | AE9: 22000 | AF9: 37000 | AG9: 9
A10: The Godfather: Part II | B10: 27132 | C10: 1974 | D10: 1970s | E10: Color | F10: Crime | G10: English | H10: USA | I10: R | J10: Robert De Niro | K10: Francis Ford Coppola | L10: 22000 | M10: 39960 | N10: 0 | O10: 14000 | P10: 9 | R10: The Godfather: Part II | S10: 27132 | T10: 1974 | U10: 1970s | V10: Color | W10: Crime | X10: English | Y10: USA | Z10: R | AA10: Robert De Niro | AB10: Francis Ford Coppola | AC10: 22000 | AD10: 39960 | AE10: 0 | AF10: 14000 | AG10: 9
A11: The Good, the Bad and the Ugly | B11: 24283 | C11: 1966 | D11: 1960s | E11: Color | F11: Western | G11: Italian | H11: Italy | I11: Approved | J11: Clint Eastwood | K11: Sergio Leone | L11: 16000 | M11: 16089 | N11: 0 | O11: 20000 | P11: 8.9 | R11: The Good, the Bad and the Ugly | S11: 24283 | T11: 1966 | U11: 1960s | V11: Color | W11: Western | X11: Italian | Y11: Italy | Z11: Approved | AA11: Clint Eastwood | AB11: Sergio Leone | AC11: 16000 | AD11: 16089 | AE11: 0 | AF11: 20000 | AG11: 8.9
A12: Schindler's List | B12: 34305 | C12: 1993 | D12: 1990s | E12: Black and White | F12: Biography | G12: English | H12: USA | I12: R | J12: Liam Neeson | K12: Steven Spielberg | L12: 14000 | M12: 15233 | N12: 14000 | O12: 41000 | P12: 8.9 | R12: Schindler's List | S12: 34305 | T12: 1993 | U12: 1990s | V12: Black and White | W12: Biography | X12: English | Y12: USA | Z12: R | AA12: Liam Neeson | AB12: Steven Spielberg | AC12: 14000 | AD12: 15233 | AE12: 14000 | AF12: 41000 | AG12: 8.9
A13: Pulp Fiction | B13: 34516 | C13: 1994 | D13: 1990s | E13: Color | F13: Crime | G13: English | H13: USA | I13: R | J13: Bruce Willis | K13: Quentin Tarantino | L13: 13000 | M13: 16557 | N13: 16000 | O13: 45000 | P13: 8.9 | R13: Pulp Fiction | S13: 34516 | T13: 1994 | U13: 1990s | V13: Color | W13: Crime | X13: English | Y13: USA | Z13: R | AA13: Bruce Willis | AB13: Quentin Tarantino | AC13: 13000 | AD13: 16557 | AE13: 16000 | AF13: 45000 | AG13: 8.9
A14: The Lord of the Rings: The Return of the King | B14: 37885 | C14: 2003 | D14: 2000s | E14: Color | F14: Action | G14: English | H14: USA | I14: PG-13 | J14: Orlando Bloom | K14: Peter Jackson | L14: 5000 | M14: 6434 | N14: 0 | O14: 16000 | P14: 8.9 | R14: The Lord of the Rings: The Return of the King | S14: 37885 | T14: 2003 | U14: 2000s | V14: Color | W14: Action | X14: English | Y14: USA | Z14: PG-13 | AA14: Orlando Bloom | AB14: Peter Jackson | AC14: 5000 | AD14: 6434 | AE14: 0 | AF14: 16000 | AG14: 8.9
A15: Inception | B15: 40240 | C15: 2010 | D15: 2010s | E15: Color | F15: Action | G15: English | H15: USA | I15: PG-13 | J15: Leonardo DiCaprio | K15: Christopher Nolan | L15: 29000 | M15: 81115 | N15: 22000 | O15: 175000 | P15: 8.8 | R15: Inception | S15: 40240 | T15: 2010 | U15: 2010s | V15: Color | W15: Action | X15: English | Y15: USA | Z15: PG-13 | AA15: Leonardo DiCaprio | AB15: Christopher Nolan | AC15: 29000 | AD15: 81115 | AE15: 22000 | AF15: 175000 | AG15: 8.8
A16: The Lord of the Rings: The Fellowship of the Ring | B16: 37201 | C16: 2001 | D16: 2000s | E16: Color | F16: Action | G16: English | H16: New Zealand | I16: PG-13 | J16: Christopher Lee | K16: Peter Jackson | L16: 16000 | M16: 22342 | N16: 0 | O16: 21000 | P16: 8.8 | R16: The Lord of the Rings: The Fellowship of the Ring | S16: 37201 | T16: 2001 | U16: 2000s | V16: Color | W16: Action | X16: English | Y16: New Zealand | Z16: PG-13 | AA16: Christopher Lee | AB16: Peter Jackson | AC16: 16000 | AD16: 22342 | AE16: 0 | AF16: 21000 | AG16: 8.8
A17: Forrest Gump | B17: 34651 | C17: 1994 | D17: 1990s | E17: Black and White | F17: Comedy | G17: English | H17: USA | I17: PG-13 | J17: Tom Hanks | K17: Robert Zemeckis | L17: 15000 | M17: 15700 | N17: 0 | O17: 59000 | P17: 8.8
A18: Star Wars: Episode V - The Empire Strikes Back | B18: 29331 | C18: 1980 | D18: 1980s | E18: Color | F18: Action | G18: English | H18: USA | I18: PG | J18: Harrison Ford | K18: Irvin Kershner | L18: 11000 | M18: 12643 | N18: 883 | O18: 17000 | P18: 8.8
A19: Fight Club | B19: 36253 | C19: 1999 | D19: 1990s | E19: Color | F19: Drama | G19: English | H19: USA | I19: R | J19: Brad Pitt | K19: David Fincher | L19: 11000 | M19: 13209 | N19: 21000 | O19: 48000 | P19: 8.8 | R19: Top 10 Movies by Gross Revenue
A20: Goodfellas | B20: 33069 | C20: 1990 | D20: 1990s | E20: Color | F20: Biography | G20: English | H20: USA | I20: R | J20: Robert De Niro | K20: Martin Scorsese | L20: 22000 | M20: 24783 | N20: 17000 | O20: 25000 | P20: 8.7 | R20: {=_xlfn._xlws.SORT(IMDB4[[Title]:[Gross Revenue]],19,-1)} -> Avatar | S20: 39950 | T20: 2009 | U20: 2000s | V20: Color | W20: Action | X20: English | Y20: USA | Z20: PG-13 | AA20: CCH Pounder | AB20: James Cameron | AC20: 1000 | AD20: 4834 | AE20: 0 | AF20: 33000 | AG20: 7.9 | AH20: 723 | AI20: 178 | AJ20: 760505847 | AL20: {=_xlfn.TAKE(_xlfn.ANCHORARRAY(R20),10)} -> Avatar | AM20: 39950 | AN20: 2009 | AO20: 2000s | AP20: Color | AQ20: Action | AR20: English | AS20: USA | AT20: PG-13 | AU20: CCH Pounder | AV20: James Cameron | AW20: 1000 | AX20: 4834 | AY20: 0 | AZ20: 33000 | BA20: 7.9 | BB20: 723 | BC20: 178 | BD20: 760505847
A21: The Matrix | B21: 36521 | C21: 1999 | D21: 1990s | E21: Color | F21: Action | G21: English | H21: USA | I21: R | J21: Keanu Reeves | K21: Lana Wachowski | L21: 18000 | M21: 18563 | N21: 0 | O21: 25000 | P21: 8.7 | R21: Titanic | S21: 35500 | T21: 1997 | U21: 1990s | V21: Color | W21: Drama | X21: English | Y21: USA | Z21: PG-13 | AA21: Leonardo DiCaprio | AB21: James Cameron | AC21: 29000 | AD21: 45223 | AE21: 0 | AF21: 26000 | AG21: 7.7 | AH21: 315 | AI21: 194 | AJ21: 658672302 | AL21: Titanic | AM21: 35500 | AN21: 1997 | AO21: 1990s | AP21: Color | AQ21: Drama | AR21: English | AS21: USA | AT21: PG-13 | AU21: Leonardo DiCaprio | AV21: James Cameron | AW21: 29000 | AX21: 45223 | AY21: 0 | AZ21: 26000 | BA21: 7.7 | BB21: 315 | BC21: 194 | BD21: 658672302
A22: The Lord of the Rings: The Two Towers | B22: 37321 | C22: 2002 | D22: 2000s | E22: Color | F22: Action | G22: English | H22: USA | I22: PG-13 | J22: Christopher Lee | K22: Peter Jackson | L22: 16000 | M22: 23052 | N22: 0 | O22: 10000 | P22: 8.7 | R22: Jurassic World | S22: 42188 | T22: 2015 | U22: 2010s | V22: Color | W22: Action | X22: English | Y22: USA | Z22: PG-13 | AA22: Bryce Dallas Howard | AB22: Colin Trevorrow | AC22: 3000 | AD22: 8458 | AE22: 365 | AF22: 150000 | AG22: 7 | AH22: 644 | AI22: 124 | AJ22: 652177271 | AL22: Jurassic World | AM22: 42188 | AN22: 2015 | AO22: 2010s | AP22: Color | AQ22: Action | AR22: English | AS22: USA | AT22: PG-13 | AU22: Bryce Dallas Howard | AV22: Colin Trevorrow | AW22: 3000 | AX22: 8458 | AY22: 365 | AZ22: 150000 | BA22: 7 | BB22: 644 | BC22: 124 | BD22: 652177271
A23: Star Wars: Episode IV - A New Hope | B23: 28163 | C23: 1977 | D23: 1970s | E23: Color | F23: Action | G23: English | H23: USA | I23: PG | J23: Harrison Ford | K23: George Lucas | L23: 11000 | M23: 13485 | N23: 0 | O23: 33000 | P23: 8.7 | R23: The Avengers | S23: 41118 | T23: 2012 | U23: 2010s | V23: Color | W23: Action | X23: English | Y23: USA | Z23: PG-13 | AA23: Chris Hemsworth | AB23: Joss Whedon | AC23: 26000 | AD23: 87697 | AE23: 0 | AF23: 123000 | AG23: 8.1 | AH23: 703 | AI23: 173 | AJ23: 623279547 | AL23: The Avengers | AM23: 41118 | AN23: 2012 | AO23: 2010s | AP23: Color | AQ23: Action | AR23: English | AS23: USA | AT23: PG-13 | AU23: Chris Hemsworth | AV23: Joss Whedon | AW23: 26000 | AX23: 87697 | AY23: 0 | AZ23: 123000 | BA23: 8.1 | BB23: 703 | BC23: 173 | BD23: 623279547
A24: City of God | B24: 37503 | C24: 2002 | D24: 2000s | E24: Color | F24: Crime | G24: Portuguese | H24: Brazil | I24: R | J24: Alice Braga | K24: Fernando Meirelles | L24: 1000 | M24: 1211 | N24: 353 | O24: 28000 | P24: 8.7 | R24: The Dark Knight | S24: 39577 | T24: 2008 | U24: 2000s | V24: Color | W24: Action | X24: English | Y24: USA | Z24: PG-13 | AA24: Christian Bale | AB24: Christopher Nolan | AC24: 23000 | AD24: 57802 | AE24: 22000 | AF24: 37000 | AG24: 9 | AH24: 645 | AI24: 152 | AJ24: 533316061 | AL24: The Dark Knight | AM24: 39577 | AN24: 2008 | AO24: 2000s | AP24: Color | AQ24: Action | AR24: English | AS24: USA | AT24: PG-13 | AU24: Christian Bale | AV24: Christopher Nolan | AW24: 23000 | AX24: 57802 | AY24: 22000 | AZ24: 37000 | BA24: 9 | BB24: 645 | BC24: 152 | BD24: 533316061
A25: One Flew Over the Cuckoo's Nest | B25: 27544 | C25: 1975 | D25: 1970s | E25: Color | F25: Drama | G25: English | H25: USA | I25: R | J25: Scatman Crothers | K25: Milos Forman | L25: 888 | M25: 2176 | N25: 869 | O25: 32000 | P25: 8.7 | R25: Star Wars: Episode I - The Phantom Menace | S25: 36330 | T25: 1999 | U25: 1990s | V25: Color | W25: Action | X25: English | Y25: USA | Z25: PG | AA25: Natalie Portman | AB25: George Lucas | AC25: 20000 | AD25: 37723 | AE25: 0 | AF25: 13000 | AG25: 6.5 | AH25: 320 | AI25: 136 | AJ25: 474544677 | AL25: Star Wars: Episode I - The Phantom Menace | AM25: 36330 | AN25: 1999 | AO25: 1990s | AP25: Color | AQ25: Action | AR25: English | AS25: USA | AT25: PG | AU25: Natalie Portman | AV25: George Lucas | AW25: 20000 | AX25: 37723 | AY25: 0 | AZ25: 13000 | BA25: 6.5 | BB25: 320 | BC25: 136 | BD25: 474544677
